Workbook

Sheet Test Summary
A1: NutriFit Application - Complete QA Test Case Report
A2: Automated & Manual Quality Assurance Suite | Target: Web & Android | Total Test Cases: 360
A4: Total Test Cases | B4: Passed | C4: Failed | D4: Skipped | E4: Blocked | F4: Not Executed | G4: Execution Progress
A5: =SUM(B9:B14) | B5: =COUNTIF('Selenium Tests'!N:N, "Passed") + COUNTIF('Appium E2E Tests'!N:N, "Passed") + COUNTIF('Flutter Tests'!N:N, "Passed") + COUNTIF('Functional Tests'!N:N, "Passed") + COUNTIF('Load Tests'!N:N, "Passed") + COUNTIF('Safe Vulnerability Checks'!N:N, "Passed") | C5: =COUNTIF('Selenium Tests'!N:N, "Failed") + COUNTIF('Appium E2E Tests'!N:N, "Failed") + COUNTIF('Flutter Tests'!N:N, "Failed") + COUNTIF('Functional Tests'!N:N, "Failed") + COUNTIF('Load Tests'!N:N, "Failed") + COUNTIF('Safe Vulnerability Checks'!N:N, "Failed") | D5: =COUNTIF('Selenium Tests'!N:N, "Skipped") + COUNTIF('Appium E2E Tests'!N:N, "Skipped") + COUNTIF('Flutter Tests'!N:N, "Skipped") + COUNTIF('Functional Tests'!N:N, "Skipped") + COUNTIF('Load Tests'!N:N, "Skipped") + COUNTIF('Safe Vulnerability Checks'!N:N, "Skipped") | E5: =COUNTIF('Selenium Tests'!N:N, "Blocked") + COUNTIF('Appium E2E Tests'!N:N, "Blocked") + COUNTIF('Flutter Tests'!N:N, "Blocked") + COUNTIF('Functional Tests'!N:N, "Blocked") + COUNTIF('Load Tests'!N:N, "Blocked") + COUNTIF('Safe Vulnerability Checks'!N:N, "Blocked") | F5: =COUNTIF('Selenium Tests'!N:N, "Not Executed") + COUNTIF('Appium E2E Tests'!N:N, "Not Executed") + COUNTIF('Flutter Tests'!N:N, "Not Executed") + COUNTIF('Functional Tests'!N:N, "Not Executed") + COUNTIF('Load Tests'!N:N, "Not Executed") + COUNTIF('Safe Vulnerability Checks'!N:N, "Not Executed") | G5: =IF(B4=0, "0%", TEXT((B4-G4)/B4, "0.0%"))
A7: 1. Testing Type Breakdown
A8: Testing Type | B8: Total Cases | C8: Passed | D8: Failed | E8: Skipped | F8: Blocked | G8: Not Executed | H8: Pass Rate %
A9: Selenium Web UI Testing | B9: 100 | C9: =COUNTIF('Selenium Tests'!N:N, "Passed") | D9: =COUNTIF('Selenium Tests'!N:N, "Failed") | E9: =COUNTIF('Selenium Tests'!N:N, "Skipped") | F9: =COUNTIF('Selenium Tests'!N:N, "Blocked") | G9: =COUNTIF('Selenium Tests'!N:N, "Not Executed") | H9: =IF(B9=0, "0%", TEXT(C9/B9, "0.0%"))
A10: Appium Android E2E Testing | B10: 90 | C10: =COUNTIF('Appium E2E Tests'!N:N, "Passed") | D10: =COUNTIF('Appium E2E Tests'!N:N, "Failed") | E10: =COUNTIF('Appium E2E Tests'!N:N, "Skipped") | F10: =COUNTIF('Appium E2E Tests'!N:N, "Blocked") | G10: =COUNTIF('Appium E2E Tests'!N:N, "Not Executed") | H10: =IF(B10=0, "0%", TEXT(C10/B10, "0.0%"))
A11: Flutter Unit and Widget Testing | B11: 60 | C11: =COUNTIF('Flutter Tests'!N:N, "Passed") | D11: =COUNTIF('Flutter Tests'!N:N, "Failed") | E11: =COUNTIF('Flutter Tests'!N:N, "Skipped") | F11: =COUNTIF('Flutter Tests'!N:N, "Blocked") | G11: =COUNTIF('Flutter Tests'!N:N, "Not Executed") | H11: =IF(B11=0, "0%", TEXT(C11/B11, "0.0%"))
A12: Functional and Integration Testing | B12: 50 | C12: =COUNTIF('Functional Tests'!N:N, "Passed") | D12: =COUNTIF('Functional Tests'!N:N, "Failed") | E12: =COUNTIF('Functional Tests'!N:N, "Skipped") | F12: =COUNTIF('Functional Tests'!N:N, "Blocked") | G12: =COUNTIF('Functional Tests'!N:N, "Not Executed") | H12: =IF(B12=0, "0%", TEXT(C12/B12, "0.0%"))
A13: Load and Performance Testing | B13: 30 | C13: =COUNTIF('Load Tests'!N:N, "Passed") | D13: =COUNTIF('Load Tests'!N:N, "Failed") | E13: =COUNTIF('Load Tests'!N:N, "Skipped") | F13: =COUNTIF('Load Tests'!N:N, "Blocked") | G13: =COUNTIF('Load Tests'!N:N, "Not Executed") | H13: =IF(B13=0, "0%", TEXT(C13/B13, "0.0%"))
A14: Safe Vulnerability and Configuration Checks | B14: 30 | C14: =COUNTIF('Safe Vulnerability Checks'!N:N, "Passed") | D14: =COUNTIF('Safe Vulnerability Checks'!N:N, "Failed") | E14: =COUNTIF('Safe Vulnerability Checks'!N:N, "Skipped") | F14: =COUNTIF('Safe Vulnerability Checks'!N:N, "Blocked") | G14: =COUNTIF('Safe Vulnerability Checks'!N:N, "Not Executed") | H14: =IF(B14=0, "0%", TEXT(C14/B14, "0.0%"))
A15: Total Suite | B15: =SUM(B9:B14) | C15: =SUM(C9:C14) | D15: =SUM(D9:D14) | E15: =SUM(E9:E14) | F15: =SUM(F9:F14) | G15: =SUM(G9:G14) | H15: =IF(B15=0, "0%", TEXT(C15/B15, "0.0%"))
A17: 2. Module-Wise Test Coverage Summary (All 37 Modules)
A18: Module Name | B18: Total Cases | C18: Passed | D18: Failed | E18: Skipped | F18: Blocked | G18: Not Executed
A19: Splash | B19: =COUNTIF('Selenium Tests'!C:C, A19)+COUNTIF('Appium E2E Tests'!C:C, A19)+COUNTIF('Flutter Tests'!C:C, A19)+COUNTIF('Functional Tests'!C:C, A19)+COUNTIF('Load Tests'!C:C, A19)+COUNTIF('Safe Vulnerability Checks'!C:C, A19) | C19: =COUNTIFS('Selenium Tests'!C:C, A19, 'Selenium Tests'!N:N, "Passed")+COUNTIFS('Appium E2E Tests'!C:C, A19, 'Appium E2E Tests'!N:N, "Passed")+COUNTIFS('Flutter Tests'!C:C, A19, 'Flutter Tests'!N:N, "Passed")+COUNTIFS('Functional Tests'!C:C, A19, 'Functional Tests'!N:N, "Passed")+COUNTIFS('Load Tests'!C:C, A19, 'Load Tests'!N:N, "Passed")+COUNTIFS('Safe Vulnerability Checks'!C:C, A19, 'Safe Vulnerability Checks'!N:N, "Passed") | D19: =COUNTIFS('Selenium Tests'!C:C, A19, 'Selenium Tests'!N:N, "Failed")+COUNTIFS('Appium E2E Tests'!C:C, A19, 'Appium E2E Tests'!N:N, "Failed")+COUNTIFS('Flutter Tests'!C:C, A19, 'Flutter Tests'!N:N, "Failed")+COUNTIFS('Functional Tests'!C:C, A19, 'Functional Tests'!N:N, "Failed")+COUNTIFS('Load Tests'!C:C, A19, 'Load Tests'!N:N, "Failed")+COUNTIFS('Safe Vulnerability Checks'!C:C, A19, 'Safe Vulnerability Checks'!N:N, "Failed") | E19: =COUNTIFS('Selenium Tests'!C:C, A19, 'Selenium Tests'!N:N, "Skipped")+COUNTIFS('Appium E2E Tests'!C:C, A19, 'Appium E2E Tests'!N:N, "Skipped")+COUNTIFS('Flutter Tests'!C:C, A19, 'Flutter Tests'!N:N, "Skipped")+COUNTIFS('Functional Tests'!C:C, A19, 'Functional Tests'!N:N, "Skipped")+COUNTIFS('Load Tests'!C:C, A19, 'Load Tests'!N:N, "Skipped")+COUNTIFS('Safe Vulnerability Checks'!C:C, A19, 'Safe Vulnerability Checks'!N:N, "Skipped") | F19: =COUNTIFS('Selenium Tests'!C:C, A19, 'Selenium Tests'!N:N, "Blocked")+COUNTIFS('Appium E2E Tests'!C:C, A19, 'Appium E2E Tests'!N:N, "Blocked")+COUNTIFS('Flutter Tests'!C:C, A19, 'Flutter Tests'!N:N, "Blocked")+COUNTIFS('Functional Tests'!C:C, A19, 'Functional Tests'!N:N, "Blocked")+COUNTIFS('Load Tests'!C:C, A19, 'Load Tests'!N:N, "Blocked")+COUNTIFS('Safe Vulnerability Checks'!C:C, A19, 'Safe Vulnerability Checks'!N:N, "Blocked") | G19: =COUNTIFS('Selenium Tests'!C:C, A19, 'Selenium Tests'!N:N, "Not Executed")+COUNTIFS('Appium E2E Tests'!C:C, A19, 'Appium E2E Tests'!N:N, "Not Executed")+COUNTIFS('Flutter Tests'!C:C, A19, 'Flutter Tests'!N:N, "Not Executed")+COUNTIFS('Functional Tests'!C:C, A19, 'Functional Tests'!N:N, "Not Executed")+COUNTIFS('Load Tests'!C:C, A19, 'Load Tests'!N:N, "Not Executed")+COUNTIFS('Safe Vulnerability Checks'!C:C, A19, 'Safe Vulnerability Checks'!N:N, "Not Executed")
A20: Login | B20: =COUNTIF('Selenium Tests'!C:C, A20)+COUNTIF('Appium E2E Tests'!C:C, A20)+COUNTIF('Flutter Tests'!C:C, A20)+COUNTIF('Functional Tests'!C:C, A20)+COUNTIF('Load Tests'!C:C, A20)+COUNTIF('Safe Vulnerability Checks'!C:C, A20) | C20: =COUNTIFS('Selenium Tests'!C:C, A20, 'Selenium Tests'!N:N, "Passed")+COUNTIFS('Appium E2E Tests'!C:C, A20, 'Appium E2E Tests'!N:N, "Passed")+COUNTIFS('Flutter Tests'!C:C, A20, 'Flutter Tests'!N:N, "Passed")+COUNTIFS('Functional Tests'!C:C, A20, 'Functional Tests'!N:N, "Passed")+COUNTIFS('Load Tests'!C:C, A20, 'Load Tests'!N:N, "Passed")+COUNTIFS('Safe Vulnerability Checks'!C:C, A20, 'Safe Vulnerability Checks'!N:N, "Passed") | D20: =COUNTIFS('Selenium Tests'!C:C, A20, 'Selenium Tests'!N:N, "Failed")+COUNTIFS('Appium E2E Tests'!C:C, A20, 'Appium E2E Tests'!N:N, "Failed")+COUNTIFS('Flutter Tests'!C:C, A20, 'Flutter Tests'!N:N, "Failed")+COUNTIFS('Functional Tests'!C:C, A20, 'Functional Tests'!N:N, "Failed")+COUNTIFS('Load Tests'!C:C, A20, 'Load Tests'!N:N, "Failed")+COUNTIFS('Safe Vulnerability Checks'!C:C, A20, 'Safe Vulnerability Checks'!N:N, "Failed") | E20: =COUNTIFS('Selenium Tests'!C:C, A20, 'Selenium Tests'!N:N, "Skipped")+COUNTIFS('Appium E2E Tests'!C:C, A20, 'Appium E2E Tests'!N:N, "Skipped")+COUNTIFS('Flutter Tests'!C:C, A20, 'Flutter Tests'!N:N, "Skipped")+COUNTIFS('Functional Tests'!C:C, A20, 'Functional Tests'!N:N, "Skipped")+COUNTIFS('Load Tests'!C:C, A20, 'Load Tests'!N:N, "Skipped")+COUNTIFS('Safe Vulnerability Checks'!C:C, A20, 'Safe Vulnerability Checks'!N:N, "Skipped") | F20: =COUNTIFS('Selenium Tests'!C:C, A20, 'Selenium Tests'!N:N, "Blocked")+COUNTIFS('Appium E2E Tests'!C:C, A20, 'Appium E2E Tests'!N:N, "Blocked")+COUNTIFS('Flutter Tests'!C:C, A20, 'Flutter Tests'!N:N, "Blocked")+COUNTIFS('Functional Tests'!C:C, A20, 'Functional Tests'!N:N, "Blocked")+COUNTIFS('Load Tests'!C:C, A20, 'Load Tests'!N:N, "Blocked")+COUNTIFS('Safe Vulnerability Checks'!C:C, A20, 'Safe Vulnerability Checks'!N:N, "Blocked") | G20: =COUNTIFS('Selenium Tests'!C:C, A20, 'Selenium Tests'!N:N, "Not Executed")+COUNTIFS('Appium E2E Tests'!C:C, A20, 'Appium E2E Tests'!N:N, "Not Executed")+COUNTIFS('Flutter Tests'!C:C, A20, 'Flutter Tests'!N:N, "Not Executed")+COUNTIFS('Functional Tests'!C:C, A20, 'Functional Tests'!N:N, "Not Executed")+COUNTIFS('Load Tests'!C:C, A20, 'Load Tests'!N:N, "Not Executed")+COUNTIFS('Safe Vulnerability Checks'!C:C, A20, 'Safe Vulnerability Checks'!N:N, "Not Executed")
A21: Signup | B21: =COUNTIF('Selenium Tests'!C:C, A21)+COUNTIF('Appium E2E Tests'!C:C, A21)+COUNTIF('Flutter Tests'!C:C, A21)+COUNTIF('Functional Tests'!C:C, A21)+COUNTIF('Load Tests'!C:C, A21)+COUNTIF('Safe Vulnerability Checks'!C:C, A21) | C21: =COUNTIFS('Selenium Tests'!C:C, A21, 'Selenium Tests'!N:N, "Passed")+COUNTIFS('Appium E2E Tests'!C:C, A21, 'Appium E2E Tests'!N:N, "Passed")+COUNTIFS('Flutter Tests'!C:C, A21, 'Flutter Tests'!N:N, "Passed")+COUNTIFS('Functional Tests'!C:C, A21, 'Functional Tests'!N:N, "Passed")+COUNTIFS('Load Tests'!C:C, A21, 'Load Tests'!N:N, "Passed")+COUNTIFS('Safe Vulnerability Checks'!C:C, A21, 'Safe Vulnerability Checks'!N:N, "Passed") | D21: =COUNTIFS('Selenium Tests'!C:C, A21, 'Selenium Tests'!N:N, "Failed")+COUNTIFS('Appium E2E Tests'!C:C, A21, 'Appium E2E Tests'!N:N, "Failed")+COUNTIFS('Flutter Tests'!C:C, A21, 'Flutter Tests'!N:N, "Failed")+COUNTIFS('Functional Tests'!C:C, A21, 'Functional Tests'!N:N, "Failed")+COUNTIFS('Load Tests'!C:C, A21, 'Load Tests'!N:N, "Failed")+COUNTIFS('Safe Vulnerability Checks'!C:C, A21, 'Safe Vulnerability Checks'!N:N, "Failed") | E21: =COUNTIFS('Selenium Tests'!C:C, A21, 'Selenium Tests'!N:N, "Skipped")+COUNTIFS('Appium E2E Tests'!C:C, A21, 'Appium E2E Tests'!N:N, "Skipped")+COUNTIFS('Flutter Tests'!C:C, A21, 'Flutter Tests'!N:N, "Skipped")+COUNTIFS('Functional Tests'!C:C, A21, 'Functional Tests'!N:N, "Skipped")+COUNTIFS('Load Tests'!C:C, A21, 'Load Tests'!N:N, "Skipped")+COUNTIFS('Safe Vulnerability Checks'!C:C, A21, 'Safe Vulnerability Checks'!N:N, "Skipped") | F21: =COUNTIFS('Selenium Tests'!C:C, A21, 'Selenium Tests'!N:N, "Blocked")+COUNTIFS('Appium E2E Tests'!C:C, A21, 'Appium E2E Tests'!N:N, "Blocked")+COUNTIFS('Flutter Tests'!C:C, A21, 'Flutter Tests'!N:N, "Blocked")+COUNTIFS('Functional Tests'!C:C, A21, 'Functional Tests'!N:N, "Blocked")+COUNTIFS('Load Tests'!C:C, A21, 'Load Tests'!N:N, "Blocked")+COUNTIFS('Safe Vulnerability Checks'!C:C, A21, 'Safe Vulnerability Checks'!N:N, "Blocked") | G21: =COUNTIFS('Selenium Tests'!C:C, A21, 'Selenium Tests'!N:N, "Not Executed")+COUNTIFS('Appium E2E Tests'!C:C, A21, 'Appium E2E Tests'!N:N, "Not Executed")+COUNTIFS('Flutter Tests'!C:C, A21, 'Flutter Tests'!N:N, "Not Executed")+COUNTIFS('Functional Tests'!C:C, A21, 'Functional Tests'!N:N, "Not Executed")+COUNTIFS('Load Tests'!C:C, A21, 'Load Tests'!N:N, "Not Executed")+COUNTIFS('Safe Vulnerability Checks'!C:C, A21, 'Safe Vulnerability Checks'!N:N, "Not Executed")
A22: Forgot Password | B22: =COUNTIF('Selenium Tests'!C:C, A22)+COUNTIF('Appium E2E Tests'!C:C, A22)+COUNTIF('Flutter Tests'!C:C, A22)+COUNTIF('Functional Tests'!C:C, A22)+COUNTIF('Load Tests'!C:C, A22)+COUNTIF('Safe Vulnerability Checks'!C:C, A22) | C22: =COUNTIFS('Selenium Tests'!C:C, A22, 'Selenium Tests'!N:N, "Passed")+COUNTIFS('Appium E2E Tests'!C:C, A22, 'Appium E2E Tests'!N:N, "Passed")+COUNTIFS('Flutter Tests'!C:C, A22, 'Flutter Tests'!N:N, "Passed")+COUNTIFS('Functional Tests'!C:C, A22, 'Functional Tests'!N:N, "Passed")+COUNTIFS('Load Tests'!C:C, A22, 'Load Tests'!N:N, "Passed")+COUNTIFS('Safe Vulnerability Checks'!C:C, A22, 'Safe Vulnerability Checks'!N:N, "Passed") | D22: =COUNTIFS('Selenium Tests'!C:C, A22, 'Selenium Tests'!N:N, "Failed")+COUNTIFS('Appium E2E Tests'!C:C, A22, 'Appium E2E Tests'!N:N, "Failed")+COUNTIFS('Flutter Tests'!C:C, A22, 'Flutter Tests'!N:N, "Failed")+COUNTIFS('Functional Tests'!C:C, A22, 'Functional Tests'!N:N, "Failed")+COUNTIFS('Load Tests'!C:C, A22, 'Load Tests'!N:N, "Failed")+COUNTIFS('Safe Vulnerability Checks'!C:C, A22, 'Safe Vulnerability Checks'!N:N, "Failed") | E22: =COUNTIFS('Selenium Tests'!C:C, A22, 'Selenium Tests'!N:N, "Skipped")+COUNTIFS('Appium E2E Tests'!C:C, A22, 'Appium E2E Tests'!N:N, "Skipped")+COUNTIFS('Flutter Tests'!C:C, A22, 'Flutter Tests'!N:N, "Skipped")+COUNTIFS('Functional Tests'!C:C, A22, 'Functional Tests'!N:N, "Skipped")+COUNTIFS('Load Tests'!C:C, A22, 'Load Tests'!N:N, "Skipped")+COUNTIFS('Safe Vulnerability Checks'!C:C, A22, 'Safe Vulnerability Checks'!N:N, "Skipped") | F22: =COUNTIFS('Selenium Tests'!C:C, A22, 'Selenium Tests'!N:N, "Blocked")+COUNTIFS('Appium E2E Tests'!C:C, A22, 'Appium E2E Tests'!N:N, "Blocked")+COUNTIFS('Flutter Tests'!C:C, A22, 'Flutter Tests'!N:N, "Blocked")+COUNTIFS('Functional Tests'!C:C, A22, 'Functional Tests'!N:N, "Blocked")+COUNTIFS('Load Tests'!C:C, A22, 'Load Tests'!N:N, "Blocked")+COUNTIFS('Safe Vulnerability Checks'!C:C, A22, 'Safe Vulnerability Checks'!N:N, "Blocked") | G22: =COUNTIFS('Selenium Tests'!C:C, A22, 'Selenium Tests'!N:N, "Not Executed")+COUNTIFS('Appium E2E Tests'!C:C, A22, 'Appium E2E Tests'!N:N, "Not Executed")+COUNTIFS('Flutter Tests'!C:C, A22, 'Flutter Tests'!N:N, "Not Executed")+COUNTIFS('Functional Tests'!C:C, A22, 'Functional Tests'!N:N, "Not Executed")+COUNTIFS('Load Tests'!C:C, A22, 'Load Tests'!N:N, "Not Executed")+COUNTIFS('Safe Vulnerability Checks'!C:C, A22, 'Safe Vulnerability Checks'!N:N, "Not Executed")
A23: Email Verification | B23: =COUNTIF('Selenium Tests'!C:C, A23)+COUNTIF('Appium E2E Tests'!C:C, A23)+COUNTIF('Flutter Tests'!C:C, A23)+COUNTIF('Functional Tests'!C:C, A23)+COUNTIF('Load Tests'!C:C, A23)+COUNTIF('Safe Vulnerability Checks'!C:C, A23) | C23: =COUNTIFS('Selenium Tests'!C:C, A23, 'Selenium Tests'!N:N, "Passed")+COUNTIFS('Appium E2E Tests'!C:C, A23, 'Appium E2E Tests'!N:N, "Passed")+COUNTIFS('Flutter Tests'!C:C, A23, 'Flutter Tests'!N:N, "Passed")+COUNTIFS('Functional Tests'!C:C, A23, 'Functional Tests'!N:N, "Passed")+COUNTIFS('Load Tests'!C:C, A23, 'Load Tests'!N:N, "Passed")+COUNTIFS('Safe Vulnerability Checks'!C:C, A23, 'Safe Vulnerability Checks'!N:N, "Passed") | D23: =COUNTIFS('Selenium Tests'!C:C, A23, 'Selenium Tests'!N:N, "Failed")+COUNTIFS('Appium E2E Tests'!C:C, A23, 'Appium E2E Tests'!N:N, "Failed")+COUNTIFS('Flutter Tests'!C:C, A23, 'Flutter Tests'!N:N, "Failed")+COUNTIFS('Functional Tests'!C:C, A23, 'Functional Tests'!N:N, "Failed")+COUNTIFS('Load Tests'!C:C, A23, 'Load Tests'!N:N, "Failed")+COUNTIFS('Safe Vulnerability Checks'!C:C, A23, 'Safe Vulnerability Checks'!N:N, "Failed") | E23: =COUNTIFS('Selenium Tests'!C:C, A23, 'Selenium Tests'!N:N, "Skipped")+COUNTIFS('Appium E2E Tests'!C:C, A23, 'Appium E2E Tests'!N:N, "Skipped")+COUNTIFS('Flutter Tests'!C:C, A23, 'Flutter Tests'!N:N, "Skipped")+COUNTIFS('Functional Tests'!C:C, A23, 'Functional Tests'!N:N, "Skipped")+COUNTIFS('Load Tests'!C:C, A23, 'Load Tests'!N:N, "Skipped")+COUNTIFS('Safe Vulnerability Checks'!C:C, A23, 'Safe Vulnerability Checks'!N:N, "Skipped") | F23: =COUNTIFS('Selenium Tests'!C:C, A23, 'Selenium Tests'!N:N, "Blocked")+COUNTIFS('Appium E2E Tests'!C:C, A23, 'Appium E2E Tests'!N:N, "Blocked")+COUNTIFS('Flutter Tests'!C:C, A23, 'Flutter Tests'!N:N, "Blocked")+COUNTIFS('Functional Tests'!C:C, A23, 'Functional Tests'!N:N, "Blocked")+COUNTIFS('Load Tests'!C:C, A23, 'Load Tests'!N:N, "Blocked")+COUNTIFS('Safe Vulnerability Checks'!C:C, A23, 'Safe Vulnerability Checks'!N:N, "Blocked") | G23: =COUNTIFS('Selenium Tests'!C:C, A23, 'Selenium Tests'!N:N, "Not Executed")+COUNTIFS('Appium E2E Tests'!C:C, A23, 'Appium E2E Tests'!N:N, "Not Executed")+COUNTIFS('Flutter Tests'!C:C, A23, 'Flutter Tests'!N:N, "Not Executed")+COUNTIFS('Functional Tests'!C:C, A23, 'Functional Tests'!N:N, "Not Executed")+COUNTIFS('Load Tests'!C:C, A23, 'Load Tests'!N:N, "Not Executed")+COUNTIFS('Safe Vulnerability Checks'!C:C, A23, 'Safe Vulnerability Checks'!N:N, "Not Executed")
A24: Onboarding | B24: =COUNTIF('Selenium Tests'!C:C, A24)+COUNTIF('Appium E2E Tests'!C:C, A24)+COUNTIF('Flutter Tests'!C:C, A24)+COUNTIF('Functional Tests'!C:C, A24)+COUNTIF('Load Tests'!C:C, A24)+COUNTIF('Safe Vulnerability Checks'!C:C, A24) | C24: =COUNTIFS('Selenium Tests'!C:C, A24, 'Selenium Tests'!N:N, "Passed")+COUNTIFS('Appium E2E Tests'!C:C, A24, 'Appium E2E Tests'!N:N, "Passed")+COUNTIFS('Flutter Tests'!C:C, A24, 'Flutter Tests'!N:N, "Passed")+COUNTIFS('Functional Tests'!C:C, A24, 'Functional Tests'!N:N, "Passed")+COUNTIFS('Load Tests'!C:C, A24, 'Load Tests'!N:N, "Passed")+COUNTIFS('Safe Vulnerability Checks'!C:C, A24, 'Safe Vulnerability Checks'!N:N, "Passed") | D24: =COUNTIFS('Selenium Tests'!C:C, A24, 'Selenium Tests'!N:N, "Failed")+COUNTIFS('Appium E2E Tests'!C:C, A24, 'Appium E2E Tests'!N:N, "Failed")+COUNTIFS('Flutter Tests'!C:C, A24, 'Flutter Tests'!N:N, "Failed")+COUNTIFS('Functional Tests'!C:C, A24, 'Functional Tests'!N:N, "Failed")+COUNTIFS('Load Tests'!C:C, A24, 'Load Tests'!N:N, "Failed")+COUNTIFS('Safe Vulnerability Checks'!C:C, A24, 'Safe Vulnerability Checks'!N:N, "Failed") | E24: =COUNTIFS('Selenium Tests'!C:C, A24, 'Selenium Tests'!N:N, "Skipped")+COUNTIFS('Appium E2E Tests'!C:C, A24, 'Appium E2E Tests'!N:N, "Skipped")+COUNTIFS('Flutter Tests'!C:C, A24, 'Flutter Tests'!N:N, "Skipped")+COUNTIFS('Functional Tests'!C:C, A24, 'Functional Tests'!N:N, "Skipped")+COUNTIFS('Load Tests'!C:C, A24, 'Load Tests'!N:N, "Skipped")+COUNTIFS('Safe Vulnerability Checks'!C:C, A24, 'Safe Vulnerability Checks'!N:N, "Skipped") | F24: =COUNTIFS('Selenium Tests'!C:C, A24, 'Selenium Tests'!N:N, "Blocked")+COUNTIFS('Appium E2E Tests'!C:C, A24, 'Appium E2E Tests'!N:N, "Blocked")+COUNTIFS('Flutter Tests'!C:C, A24, 'Flutter Tests'!N:N, "Blocked")+COUNTIFS('Functional Tests'!C:C, A24, 'Functional Tests'!N:N, "Blocked")+COUNTIFS('Load Tests'!C:C, A24, 'Load Tests'!N:N, "Blocked")+COUNTIFS('Safe Vulnerability Checks'!C:C, A24, 'Safe Vulnerability Checks'!N:N, "Blocked") | G24: =COUNTIFS('Selenium Tests'!C:C, A24, 'Selenium Tests'!N:N, "Not Executed")+COUNTIFS('Appium E2E Tests'!C:C, A24, 'Appium E2E Tests'!N:N, "Not Executed")+COUNTIFS('Flutter Tests'!C:C, A24, 'Flutter Tests'!N:N, "Not Executed")+COUNTIFS('Functional Tests'!C:C, A24, 'Functional Tests'!N:N, "Not Executed")+COUNTIFS('Load Tests'!C:C, A24, 'Load Tests'!N:N, "Not Executed")+COUNTIFS('Safe Vulnerability Checks'!C:C, A24, 'Safe Vulnerability Checks'!N:N, "Not Executed")
A25: Dashboard | B25: =COUNTIF('Selenium Tests'!C:C, A25)+COUNTIF('Appium E2E Tests'!C:C, A25)+COUNTIF('Flutter Tests'!C:C, A25)+COUNTIF('Functional Tests'!C:C, A25)+COUNTIF('Load Tests'!C:C, A25)+COUNTIF('Safe Vulnerability Checks'!C:C, A25) | C25: =COUNTIFS('Selenium Tests'!C:C, A25, 'Selenium Tests'!N:N, "Passed")+COUNTIFS('Appium E2E Tests'!C:C, A25, 'Appium E2E Tests'!N:N, "Passed")+COUNTIFS('Flutter Tests'!C:C, A25, 'Flutter Tests'!N:N, "Passed")+COUNTIFS('Functional Tests'!C:C, A25, 'Functional Tests'!N:N, "Passed")+COUNTIFS('Load Tests'!C:C, A25, 'Load Tests'!N:N, "Passed")+COUNTIFS('Safe Vulnerability Checks'!C:C, A25, 'Safe Vulnerability Checks'!N:N, "Passed") | D25: =COUNTIFS('Selenium Tests'!C:C, A25, 'Selenium Tests'!N:N, "Failed")+COUNTIFS('Appium E2E Tests'!C:C, A25, 'Appium E2E Tests'!N:N, "Failed")+COUNTIFS('Flutter Tests'!C:C, A25, 'Flutter Tests'!N:N, "Failed")+COUNTIFS('Functional Tests'!C:C, A25, 'Functional Tests'!N:N, "Failed")+COUNTIFS('Load Tests'!C:C, A25, 'Load Tests'!N:N, "Failed")+COUNTIFS('Safe Vulnerability Checks'!C:C, A25, 'Safe Vulnerability Checks'!N:N, "Failed") | E25: =COUNTIFS('Selenium Tests'!C:C, A25, 'Selenium Tests'!N:N, "Skipped")+COUNTIFS('Appium E2E Tests'!C:C, A25, 'Appium E2E Tests'!N:N, "Skipped")+COUNTIFS('Flutter Tests'!C:C, A25, 'Flutter Tests'!N:N, "Skipped")+COUNTIFS('Functional Tests'!C:C, A25, 'Functional Tests'!N:N, "Skipped")+COUNTIFS('Load Tests'!C:C, A25, 'Load Tests'!N:N, "Skipped")+COUNTIFS('Safe Vulnerability Checks'!C:C, A25, 'Safe Vulnerability Checks'!N:N, "Skipped") | F25: =COUNTIFS('Selenium Tests'!C:C, A25, 'Selenium Tests'!N:N, "Blocked")+COUNTIFS('Appium E2E Tests'!C:C, A25, 'Appium E2E Tests'!N:N, "Blocked")+COUNTIFS('Flutter Tests'!C:C, A25, 'Flutter Tests'!N:N, "Blocked")+COUNTIFS('Functional Tests'!C:C, A25, 'Functional Tests'!N:N, "Blocked")+COUNTIFS('Load Tests'!C:C, A25, 'Load Tests'!N:N, "Blocked")+COUNTIFS('Safe Vulnerability Checks'!C:C, A25, 'Safe Vulnerability Checks'!N:N, "Blocked") | G25: =COUNTIFS('Selenium Tests'!C:C, A25, 'Selenium Tests'!N:N, "Not Executed")+COUNTIFS('Appium E2E Tests'!C:C, A25, 'Appium E2E Tests'!N:N, "Not Executed")+COUNTIFS('Flutter Tests'!C:C, A25, 'Flutter Tests'!N:N, "Not Executed")+COUNTIFS('Functional Tests'!C:C, A25, 'Functional Tests'!N:N, "Not Executed")+COUNTIFS('Load Tests'!C:C, A25, 'Load Tests'!N:N, "Not Executed")+COUNTIFS('Safe Vulnerability Checks'!C:C, A25, 'Safe Vulnerability Checks'!N:N, "Not Executed")
A26: Profile | B26: =COUNTIF('Selenium Tests'!C:C, A26)+COUNTIF('Appium E2E Tests'!C:C, A26)+COUNTIF('Flutter Tests'!C:C, A26)+COUNTIF('Functional Tests'!C:C, A26)+COUNTIF('Load Tests'!C:C, A26)+COUNTIF('Safe Vulnerability Checks'!C:C, A26) | C26: =COUNTIFS('Selenium Tests'!C:C, A26, 'Selenium Tests'!N:N, "Passed")+COUNTIFS('Appium E2E Tests'!C:C, A26, 'Appium E2E Tests'!N:N, "Passed")+COUNTIFS('Flutter Tests'!C:C, A26, 'Flutter Tests'!N:N, "Passed")+COUNTIFS('Functional Tests'!C:C, A26, 'Functional Tests'!N:N, "Passed")+COUNTIFS('Load Tests'!C:C, A26, 'Load Tests'!N:N, "Passed")+COUNTIFS('Safe Vulnerability Checks'!C:C, A26, 'Safe Vulnerability Checks'!N:N, "Passed") | D26: =COUNTIFS('Selenium Tests'!C:C, A26, 'Selenium Tests'!N:N, "Failed")+COUNTIFS('Appium E2E Tests'!C:C, A26, 'Appium E2E Tests'!N:N, "Failed")+COUNTIFS('Flutter Tests'!C:C, A26, 'Flutter Tests'!N:N, "Failed")+COUNTIFS('Functional Tests'!C:C, A26, 'Functional Tests'!N:N, "Failed")+COUNTIFS('Load Tests'!C:C, A26, 'Load Tests'!N:N, "Failed")+COUNTIFS('Safe Vulnerability Checks'!C:C, A26, 'Safe Vulnerability Checks'!N:N, "Failed") | E26: =COUNTIFS('Selenium Tests'!C:C, A26, 'Selenium Tests'!N:N, "Skipped")+COUNTIFS('Appium E2E Tests'!C:C, A26, 'Appium E2E Tests'!N:N, "Skipped")+COUNTIFS('Flutter Tests'!C:C, A26, 'Flutter Tests'!N:N, "Skipped")+COUNTIFS('Functional Tests'!C:C, A26, 'Functional Tests'!N:N, "Skipped")+COUNTIFS('Load Tests'!C:C, A26, 'Load Tests'!N:N, "Skipped")+COUNTIFS('Safe Vulnerability Checks'!C:C, A26, 'Safe Vulnerability Checks'!N:N, "Skipped") | F26: =COUNTIFS('Selenium Tests'!C:C, A26, 'Selenium Tests'!N:N, "Blocked")+COUNTIFS('Appium E2E Tests'!C:C, A26, 'Appium E2E Tests'!N:N, "Blocked")+COUNTIFS('Flutter Tests'!C:C, A26, 'Flutter Tests'!N:N, "Blocked")+COUNTIFS('Functional Tests'!C:C, A26, 'Functional Tests'!N:N, "Blocked")+COUNTIFS('Load Tests'!C:C, A26, 'Load Tests'!N:N, "Blocked")+COUNTIFS('Safe Vulnerability Checks'!C:C, A26, 'Safe Vulnerability Checks'!N:N, "Blocked") | G26: =COUNTIFS('Selenium Tests'!C:C, A26, 'Selenium Tests'!N:N, "Not Executed")+COUNTIFS('Appium E2E Tests'!C:C, A26, 'Appium E2E Tests'!N:N, "Not Executed")+COUNTIFS('Flutter Tests'!C:C, A26, 'Flutter Tests'!N:N, "Not Executed")+COUNTIFS('Functional Tests'!C:C, A26, 'Functional Tests'!N:N, "Not Executed")+COUNTIFS('Load Tests'!C:C, A26, 'Load Tests'!N:N, "Not Executed")+COUNTIFS('Safe Vulnerability Checks'!C:C, A26, 'Safe Vulnerability Checks'!N:N, "Not Executed")
A27: Language Settings | B27: =COUNTIF('Selenium Tests'!C:C, A27)+COUNTIF('Appium E2E Tests'!C:C, A27)+COUNTIF('Flutter Tests'!C:C, A27)+COUNTIF('Functional Tests'!C:C, A27)+COUNTIF('Load Tests'!C:C, A27)+COUNTIF('Safe Vulnerability Checks'!C:C, A27) | C27: =COUNTIFS('Selenium Tests'!C:C, A27, 'Selenium Tests'!N:N, "Passed")+COUNTIFS('Appium E2E Tests'!C:C, A27, 'Appium E2E Tests'!N:N, "Passed")+COUNTIFS('Flutter Tests'!C:C, A27, 'Flutter Tests'!N:N, "Passed")+COUNTIFS('Functional Tests'!C:C, A27, 'Functional Tests'!N:N, "Passed")+COUNTIFS('Load Tests'!C:C, A27, 'Load Tests'!N:N, "Passed")+COUNTIFS('Safe Vulnerability Checks'!C:C, A27, 'Safe Vulnerability Checks'!N:N, "Passed") | D27: =COUNTIFS('Selenium Tests'!C:C, A27, 'Selenium Tests'!N:N, "Failed")+COUNTIFS('Appium E2E Tests'!C:C, A27, 'Appium E2E Tests'!N:N, "Failed")+COUNTIFS('Flutter Tests'!C:C, A27, 'Flutter Tests'!N:N, "Failed")+COUNTIFS('Functional Tests'!C:C, A27, 'Functional Tests'!N:N, "Failed")+COUNTIFS('Load Tests'!C:C, A27, 'Load Tests'!N:N, "Failed")+COUNTIFS('Safe Vulnerability Checks'!C:C, A27, 'Safe Vulnerability Checks'!N:N, "Failed") | E27: =COUNTIFS('Selenium Tests'!C:C, A27, 'Selenium Tests'!N:N, "Skipped")+COUNTIFS('Appium E2E Tests'!C:C, A27, 'Appium E2E Tests'!N:N, "Skipped")+COUNTIFS('Flutter Tests'!C:C, A27, 'Flutter Tests'!N:N, "Skipped")+COUNTIFS('Functional Tests'!C:C, A27, 'Functional Tests'!N:N, "Skipped")+COUNTIFS('Load Tests'!C:C, A27, 'Load Tests'!N:N, "Skipped")+COUNTIFS('Safe Vulnerability Checks'!C:C, A27, 'Safe Vulnerability Checks'!N:N, "Skipped") | F27: =COUNTIFS('Selenium Tests'!C:C, A27, 'Selenium Tests'!N:N, "Blocked")+COUNTIFS('Appium E2E Tests'!C:C, A27, 'Appium E2E Tests'!N:N, "Blocked")+COUNTIFS('Flutter Tests'!C:C, A27, 'Flutter Tests'!N:N, "Blocked")+COUNTIFS('Functional Tests'!C:C, A27, 'Functional Tests'!N:N, "Blocked")+COUNTIFS('Load Tests'!C:C, A27, 'Load Tests'!N:N, "Blocked")+COUNTIFS('Safe Vulnerability Checks'!C:C, A27, 'Safe Vulnerability Checks'!N:N, "Blocked") | G27: =COUNTIFS('Selenium Tests'!C:C, A27, 'Selenium Tests'!N:N, "Not Executed")+COUNTIFS('Appium E2E Tests'!C:C, A27, 'Appium E2E Tests'!N:N, "Not Executed")+COUNTIFS('Flutter Tests'!C:C, A27, 'Flutter Tests'!N:N, "Not Executed")+COUNTIFS('Functional Tests'!C:C, A27, 'Functional Tests'!N:N, "Not Executed")+COUNTIFS('Load Tests'!C:C, A27, 'Load Tests'!N:N, "Not Executed")+COUNTIFS('Safe Vulnerability Checks'!C:C, A27, 'Safe Vulnerability Checks'!N:N, "Not Executed")
A28: AI Trainer | B28: =COUNTIF('Selenium Tests'!C:C, A28)+COUNTIF('Appium E2E Tests'!C:C, A28)+COUNTIF('Flutter Tests'!C:C, A28)+COUNTIF('Functional Tests'!C:C, A28)+COUNTIF('Load Tests'!C:C, A28)+COUNTIF('Safe Vulnerability Checks'!C:C, A28) | C28: =COUNTIFS('Selenium Tests'!C:C, A28, 'Selenium Tests'!N:N, "Passed")+COUNTIFS('Appium E2E Tests'!C:C, A28, 'Appium E2E Tests'!N:N, "Passed")+COUNTIFS('Flutter Tests'!C:C, A28, 'Flutter Tests'!N:N, "Passed")+COUNTIFS('Functional Tests'!C:C, A28, 'Functional Tests'!N:N, "Passed")+COUNTIFS('Load Tests'!C:C, A28, 'Load Tests'!N:N, "Passed")+COUNTIFS('Safe Vulnerability Checks'!C:C, A28, 'Safe Vulnerability Checks'!N:N, "Passed") | D28: =COUNTIFS('Selenium Tests'!C:C, A28, 'Selenium Tests'!N:N, "Failed")+COUNTIFS('Appium E2E Tests'!C:C, A28, 'Appium E2E Tests'!N:N, "Failed")+COUNTIFS('Flutter Tests'!C:C, A28, 'Flutter Tests'!N:N, "Failed")+COUNTIFS('Functional Tests'!C:C, A28, 'Functional Tests'!N:N, "Failed")+COUNTIFS('Load Tests'!C:C, A28, 'Load Tests'!N:N, "Failed")+COUNTIFS('Safe Vulnerability Checks'!C:C, A28, 'Safe Vulnerability Checks'!N:N, "Failed") | E28: =COUNTIFS('Selenium Tests'!C:C, A28, 'Selenium Tests'!N:N, "Skipped")+COUNTIFS('Appium E2E Tests'!C:C, A28, 'Appium E2E Tests'!N:N, "Skipped")+COUNTIFS('Flutter Tests'!C:C, A28, 'Flutter Tests'!N:N, "Skipped")+COUNTIFS('Functional Tests'!C:C, A28, 'Functional Tests'!N:N, "Skipped")+COUNTIFS('Load Tests'!C:C, A28, 'Load Tests'!N:N, "Skipped")+COUNTIFS('Safe Vulnerability Checks'!C:C, A28, 'Safe Vulnerability Checks'!N:N, "Skipped") | F28: =COUNTIFS('Selenium Tests'!C:C, A28, 'Selenium Tests'!N:N, "Blocked")+COUNTIFS('Appium E2E Tests'!C:C, A28, 'Appium E2E Tests'!N:N, "Blocked")+COUNTIFS('Flutter Tests'!C:C, A28, 'Flutter Tests'!N:N, "Blocked")+COUNTIFS('Functional Tests'!C:C, A28, 'Functional Tests'!N:N, "Blocked")+COUNTIFS('Load Tests'!C:C, A28, 'Load Tests'!N:N, "Blocked")+COUNTIFS('Safe Vulnerability Checks'!C:C, A28, 'Safe Vulnerability Checks'!N:N, "Blocked") | G28: =COUNTIFS('Selenium Tests'!C:C, A28, 'Selenium Tests'!N:N, "Not Executed")+COUNTIFS('Appium E2E Tests'!C:C, A28, 'Appium E2E Tests'!N:N, "Not Executed")+COUNTIFS('Flutter Tests'!C:C, A28, 'Flutter Tests'!N:N, "Not Executed")+COUNTIFS('Functional Tests'!C:C, A28, 'Functional Tests'!N:N, "Not Executed")+COUNTIFS('Load Tests'!C:C, A28, 'Load Tests'!N:N, "Not Executed")+COUNTIFS('Safe Vulnerability Checks'!C:C, A28, 'Safe Vulnerability Checks'!N:N, "Not Executed")
A29: Workout Plan | B29: =COUNTIF('Selenium Tests'!C:C, A29)+COUNTIF('Appium E2E Tests'!C:C, A29)+COUNTIF('Flutter Tests'!C:C, A29)+COUNTIF('Functional Tests'!C:C, A29)+COUNTIF('Load Tests'!C:C, A29)+COUNTIF('Safe Vulnerability Checks'!C:C, A29) | C29: =COUNTIFS('Selenium Tests'!C:C, A29, 'Selenium Tests'!N:N, "Passed")+COUNTIFS('Appium E2E Tests'!C:C, A29, 'Appium E2E Tests'!N:N, "Passed")+COUNTIFS('Flutter Tests'!C:C, A29, 'Flutter Tests'!N:N, "Passed")+COUNTIFS('Functional Tests'!C:C, A29, 'Functional Tests'!N:N, "Passed")+COUNTIFS('Load Tests'!C:C, A29, 'Load Tests'!N:N, "Passed")+COUNTIFS('Safe Vulnerability Checks'!C:C, A29, 'Safe Vulnerability Checks'!N:N, "Passed") | D29: =COUNTIFS('Selenium Tests'!C:C, A29, 'Selenium Tests'!N:N, "Failed")+COUNTIFS('Appium E2E Tests'!C:C, A29, 'Appium E2E Tests'!N:N, "Failed")+COUNTIFS('Flutter Tests'!C:C, A29, 'Flutter Tests'!N:N, "Failed")+COUNTIFS('Functional Tests'!C:C, A29, 'Functional Tests'!N:N, "Failed")+COUNTIFS('Load Tests'!C:C, A29, 'Load Tests'!N:N, "Failed")+COUNTIFS('Safe Vulnerability Checks'!C:C, A29, 'Safe Vulnerability Checks'!N:N, "Failed") | E29: =COUNTIFS('Selenium Tests'!C:C, A29, 'Selenium Tests'!N:N, "Skipped")+COUNTIFS('Appium E2E Tests'!C:C, A29, 'Appium E2E Tests'!N:N, "Skipped")+COUNTIFS('Flutter Tests'!C:C, A29, 'Flutter Tests'!N:N, "Skipped")+COUNTIFS('Functional Tests'!C:C, A29, 'Functional Tests'!N:N, "Skipped")+COUNTIFS('Load Tests'!C:C, A29, 'Load Tests'!N:N, "Skipped")+COUNTIFS('Safe Vulnerability Checks'!C:C, A29, 'Safe Vulnerability Checks'!N:N, "Skipped") | F29: =COUNTIFS('Selenium Tests'!C:C, A29, 'Selenium Tests'!N:N, "Blocked")+COUNTIFS('Appium E2E Tests'!C:C, A29, 'Appium E2E Tests'!N:N, "Blocked")+COUNTIFS('Flutter Tests'!C:C, A29, 'Flutter Tests'!N:N, "Blocked")+COUNTIFS('Functional Tests'!C:C, A29, 'Functional Tests'!N:N, "Blocked")+COUNTIFS('Load Tests'!C:C, A29, 'Load Tests'!N:N, "Blocked")+COUNTIFS('Safe Vulnerability Checks'!C:C, A29, 'Safe Vulnerability Checks'!N:N, "Blocked") | G29: =COUNTIFS('Selenium Tests'!C:C, A29, 'Selenium Tests'!N:N, "Not Executed")+COUNTIFS('Appium E2E Tests'!C:C, A29, 'Appium E2E Tests'!N:N, "Not Executed")+COUNTIFS('Flutter Tests'!C:C, A29, 'Flutter Tests'!N:N, "Not Executed")+COUNTIFS('Functional Tests'!C:C, A29, 'Functional Tests'!N:N, "Not Executed")+COUNTIFS('Load Tests'!C:C, A29, 'Load Tests'!N:N, "Not Executed")+COUNTIFS('Safe Vulnerability Checks'!C:C, A29, 'Safe Vulnerability Checks'!N:N, "Not Executed")
A30: Diet Plan | B30: =COUNTIF('Selenium Tests'!C:C, A30)+COUNTIF('Appium E2E Tests'!C:C, A30)+COUNTIF('Flutter Tests'!C:C, A30)+COUNTIF('Functional Tests'!C:C, A30)+COUNTIF('Load Tests'!C:C, A30)+COUNTIF('Safe Vulnerability Checks'!C:C, A30) | C30: =COUNTIFS('Selenium Tests'!C:C, A30, 'Selenium Tests'!N:N, "Passed")+COUNTIFS('Appium E2E Tests'!C:C, A30, 'Appium E2E Tests'!N:N, "Passed")+COUNTIFS('Flutter Tests'!C:C, A30, 'Flutter Tests'!N:N, "Passed")+COUNTIFS('Functional Tests'!C:C, A30, 'Functional Tests'!N:N, "Passed")+COUNTIFS('Load Tests'!C:C, A30, 'Load Tests'!N:N, "Passed")+COUNTIFS('Safe Vulnerability Checks'!C:C, A30, 'Safe Vulnerability Checks'!N:N, "Passed") | D30: =COUNTIFS('Selenium Tests'!C:C, A30, 'Selenium Tests'!N:N, "Failed")+COUNTIFS('Appium E2E Tests'!C:C, A30, 'Appium E2E Tests'!N:N, "Failed")+COUNTIFS('Flutter Tests'!C:C, A30, 'Flutter Tests'!N:N, "Failed")+COUNTIFS('Functional Tests'!C:C, A30, 'Functional Tests'!N:N, "Failed")+COUNTIFS('Load Tests'!C:C, A30, 'Load Tests'!N:N, "Failed")+COUNTIFS('Safe Vulnerability Checks'!C:C, A30, 'Safe Vulnerability Checks'!N:N, "Failed") | E30: =COUNTIFS('Selenium Tests'!C:C, A30, 'Selenium Tests'!N:N, "Skipped")+COUNTIFS('Appium E2E Tests'!C:C, A30, 'Appium E2E Tests'!N:N, "Skipped")+COUNTIFS('Flutter Tests'!C:C, A30, 'Flutter Tests'!N:N, "Skipped")+COUNTIFS('Functional Tests'!C:C, A30, 'Functional Tests'!N:N, "Skipped")+COUNTIFS('Load Tests'!C:C, A30, 'Load Tests'!N:N, "Skipped")+COUNTIFS('Safe Vulnerability Checks'!C:C, A30, 'Safe Vulnerability Checks'!N:N, "Skipped") | F30: =COUNTIFS('Selenium Tests'!C:C, A30, 'Selenium Tests'!N:N, "Blocked")+COUNTIFS('Appium E2E Tests'!C:C, A30, 'Appium E2E Tests'!N:N, "Blocked")+COUNTIFS('Flutter Tests'!C:C, A30, 'Flutter Tests'!N:N, "Blocked")+COUNTIFS('Functional Tests'!C:C, A30, 'Functional Tests'!N:N, "Blocked")+COUNTIFS('Load Tests'!C:C, A30, 'Load Tests'!N:N, "Blocked")+COUNTIFS('Safe Vulnerability Checks'!C:C, A30, 'Safe Vulnerability Checks'!N:N, "Blocked") | G30: =COUNTIFS('Selenium Tests'!C:C, A30, 'Selenium Tests'!N:N, "Not Executed")+COUNTIFS('Appium E2E Tests'!C:C, A30, 'Appium E2E Tests'!N:N, "Not Executed")+COUNTIFS('Flutter Tests'!C:C, A30, 'Flutter Tests'!N:N, "Not Executed")+COUNTIFS('Functional Tests'!C:C, A30, 'Functional Tests'!N:N, "Not Executed")+COUNTIFS('Load Tests'!C:C, A30, 'Load Tests'!N:N, "Not Executed")+COUNTIFS('Safe Vulnerability Checks'!C:C, A30, 'Safe Vulnerability Checks'!N:N, "Not Executed")
... A55: Logout | B55: =COUNTIF('Selenium Tests'!C:C, A55)+COUNTIF('Appium E2E Tests'!C:C, A55)+COUNTIF('Flutter Tests'!C:C, A55)+COUNTIF('Functional Tests'!C:C, A55)+COUNTIF('Load Tests'!C:C, A55)+COUNTIF('Safe Vulnerability Checks'!C:C, A55) | C55: =COUNTIFS('Selenium Tests'!C:C, A55, 'Selenium Tests'!N:N, "Passed")+COUNTIFS('Appium E2E Tests'!C:C, A55, 'Appium E2E Tests'!N:N, "Passed")+COUNTIFS('Flutter Tests'!C:C, A55, 'Flutter Tests'!N:N, "Passed")+COUNTIFS('Functional Tests'!C:C, A55, 'Functional Tests'!N:N, "Passed")+COUNTIFS('Load Tests'!C:C, A55, 'Load Tests'!N:N, "Passed")+COUNTIFS('Safe Vulnerability Checks'!C:C, A55, 'Safe Vulnerability Checks'!N:N, "Passed") | D55: =COUNTIFS('Selenium Tests'!C:C, A55, 'Selenium Tests'!N:N, "Failed")+COUNTIFS('Appium E2E Tests'!C:C, A55, 'Appium E2E Tests'!N:N, "Failed")+COUNTIFS('Flutter Tests'!C:C, A55, 'Flutter Tests'!N:N, "Failed")+COUNTIFS('Functional Tests'!C:C, A55, 'Functional Tests'!N:N, "Failed")+COUNTIFS('Load Tests'!C:C, A55, 'Load Tests'!N:N, "Failed")+COUNTIFS('Safe Vulnerability Checks'!C:C, A55, 'Safe Vulnerability Checks'!N:N, "Failed") | E55: =COUNTIFS('Selenium Tests'!C:C, A55, 'Selenium Tests'!N:N, "Skipped")+COUNTIFS('Appium E2E Tests'!C:C, A55, 'Appium E2E Tests'!N:N, "Skipped")+COUNTIFS('Flutter Tests'!C:C, A55, 'Flutter Tests'!N:N, "Skipped")+COUNTIFS('Functional Tests'!C:C, A55, 'Functional Tests'!N:N, "Skipped")+COUNTIFS('Load Tests'!C:C, A55, 'Load Tests'!N:N, "Skipped")+COUNTIFS('Safe Vulnerability Checks'!C:C, A55, 'Safe Vulnerability Checks'!N:N, "Skipped") | F55: =COUNTIFS('Selenium Tests'!C:C, A55, 'Selenium Tests'!N:N, "Blocked")+COUNTIFS('Appium E2E Tests'!C:C, A55, 'Appium E2E Tests'!N:N, "Blocked")+COUNTIFS('Flutter Tests'!C:C, A55, 'Flutter Tests'!N:N, "Blocked")+COUNTIFS('Functional Tests'!C:C, A55, 'Functional Tests'!N:N, "Blocked")+COUNTIFS('Load Tests'!C:C, A55, 'Load Tests'!N:N, "Blocked")+COUNTIFS('Safe Vulnerability Checks'!C:C, A55, 'Safe Vulnerability Checks'!N:N, "Blocked") | G55: =COUNTIFS('Selenium Tests'!C:C, A55, 'Selenium Tests'!N:N, "Not Executed")+COUNTIFS('Appium E2E Tests'!C:C, A55, 'Appium E2E Tests'!N:N, "Not Executed")+COUNTIFS('Flutter Tests'!C:C, A55, 'Flutter Tests'!N:N, "Not Executed")+COUNTIFS('Functional Tests'!C:C, A55, 'Functional Tests'!N:N, "Not Executed")+COUNTIFS('Load Tests'!C:C, A55, 'Load Tests'!N:N, "Not Executed")+COUNTIFS('Safe Vulnerability Checks'!C:C, A55, 'Safe Vulnerability Checks'!N:N, "Not Executed")
A56: Total All Modules | B56: =SUM(B19:B55) | C56: =SUM(C19:C55) | D56: =SUM(D19:D55) | E56: =SUM(E19:E55) | F56: =SUM(F19:F55) | G56: =SUM(G19:G55)

Sheet Selenium Tests
A1: Test Case ID | B1: Testing Type | C1: Module | D1: Test Scenario | E1: Test Case Title | F1: Objective | G1: Preconditions | H1: Test Steps | I1: Test Data | J1: Expected Result | K1: Actual Result | L1: Priority | M1: Severity | N1: Status | O1: Evidence Path | P1: Remarks
A2: SEL-WEB-001 | B2: Selenium Web UI Testing | C2: Splash | D2: Verify page load responsiveness across desktop break points in Splash module | E2: Web UI - Splash - Verify page load responsiveness across desktop break points (#1) | F2: Ensure Splash web UI component operates seamlessly under Chrome/Firefox/Edge Selenium driver. | G2: Browser session active, navigated to NutriFit Web app Splash route. | H2: 1. Open NutriFit Web app on Chrome/Edge. 2. Navigate to Splash screen. 3. Launch web browser at 1920x1080 resolution, navigate to portal, verify layout grid and header alignment. 4. Capture DOM state and screenshot. | I2: Module: Splash, Viewport: 1920x1080, Data: Standard viewport 1920x1080 | J2: Layout scales seamlessly without horizontal overflow or overlapping text elements. on Splash module. | K2: Pending Execution | L2: Medium | M2: Moderate | N2: Not Executed | O2: evidence/sel-web-001_screenshot.png | P2: Automated baseline generation
A3: SEL-WEB-002 | B3: Selenium Web UI Testing | C3: Login | D3: Verify form input validations and error hints in Login module | E3: Web UI - Login - Verify form input validations and error hints (#2) | F3: Ensure Login web UI component operates seamlessly under Chrome/Firefox/Edge Selenium driver. | G3: Browser session active, navigated to NutriFit Web app Login route. | H3: 1. Open NutriFit Web app on Chrome/Edge. 2. Navigate to Login screen. 3. Focus input field, enter invalid format data, trigger blur event, inspect validation error badge. 4. Capture DOM state and screenshot. | I3: Module: Login, Viewport: 1920x1080, Data: Invalid test string / out-of-bounds input | J3: Clear validation message displayed immediately under field. on Login module. | K3: Pending Execution | L3: Medium | M3: Major | N3: Not Executed | O3: evidence/sel-web-002_screenshot.png | P3: Automated baseline generation
A4: SEL-WEB-003 | B4: Selenium Web UI Testing | C4: Signup | D4: Verify interactive button states and hover effects in Signup module | E4: Web UI - Signup - Verify interactive button states and hover effects (#3) | F4: Ensure Signup web UI component operates seamlessly under Chrome/Firefox/Edge Selenium driver. | G4: Browser session active, navigated to NutriFit Web app Signup route. | H4: 1. Open NutriFit Web app on Chrome/Edge. 2. Navigate to Signup screen. 3. Hover mouse over primary action button, verify CSS transition, click button. 4. Capture DOM state and screenshot. | I4: Module: Signup, Viewport: 1920x1080, Data: Primary CTA button selector | J4: Button transforms smoothly on hover and handles click event correctly. on Signup module. | K4: Pending Execution | L4: High | M4: Moderate | N4: Not Executed | O4: evidence/sel-web-003_screenshot.png | P4: Automated baseline generation
A5: SEL-WEB-004 | B5: Selenium Web UI Testing | C5: Forgot Password | D5: Verify modal dialog overlay behavior in Forgot Password module | E5: Web UI - Forgot Password - Verify modal dialog overlay behavior (#4) | F5: Ensure Forgot Password web UI component operates seamlessly under Chrome/Firefox/Edge Selenium driver. | G5: Browser session active, navigated to NutriFit Web app Forgot Password route. | H5: 1. Open NutriFit Web app on Chrome/Edge. 2. Navigate to Forgot Password screen. 3. Trigger action opening dynamic modal, verify backdrop blur, click close icon. 4. Capture DOM state and screenshot. | I5: Module: Forgot Password, Viewport: 1920x1080, Data: Modal trigger event | J5: Modal opens centered with focus trap; closes cleanly on overlay/icon click. on Forgot Password module. | K5: Pending Execution | L5: Medium | M5: Major | N5: Not Executed | O5: evidence/sel-web-004_screenshot.png | P5: Automated baseline generation
A6: SEL-WEB-005 | B6: Selenium Web UI Testing | C6: Email Verification | D6: Verify table sorting and pagination controls in Email Verification module | E6: Web UI - Email Verification - Verify table sorting and pagination controls (#5) | F6: Ensure Email Verification web UI component operates seamlessly under Chrome/Firefox/Edge Selenium driver. | G6: Browser session active, navigated to NutriFit Web app Email Verification route. | H6: 1. Open NutriFit Web app on Chrome/Edge. 2. Navigate to Email Verification screen. 3. Navigate to list view, click table column header for sorting, click next page button. 4. Capture DOM state and screenshot. | I6: Module: Email Verification, Viewport: 1920x1080, Data: Page size = 10 | J6: Table updates sorted order instantly; page 2 records load cleanly. on Email Verification module. | K6: Pending Execution | L6: Low | M6: Moderate | N6: Not Executed | O6: evidence/sel-web-005_screenshot.png | P6: Automated baseline generation
A7: SEL-WEB-006 | B7: Selenium Web UI Testing | C7: Onboarding | D7: Verify theme switching (Dark/Light mode) on Web in Onboarding module | E7: Web UI - Onboarding - Verify theme switching (Dark/Light mode) on Web (#6) | F7: Ensure Onboarding web UI component operates seamlessly under Chrome/Firefox/Edge Selenium driver. | G7: Browser session active, navigated to NutriFit Web app Onboarding route. | H7: 1. Open NutriFit Web app on Chrome/Edge. 2. Navigate to Onboarding screen. 3. Click theme toggle switch in global header navbar. 4. Capture DOM state and screenshot. | I7: Module: Onboarding, Viewport: 1920x1080, Data: Theme toggle selector | J7: UI colors switch smoothly across all visible DOM containers. on Onboarding module. | K7: Pending Execution | L7: High | M7: Major | N7: Not Executed | O7: evidence/sel-web-006_screenshot.png | P7: Automated baseline generation
A8: SEL-WEB-007 | B8: Selenium Web UI Testing | C8: Dashboard | D8: Verify navigation drawer opening and item selection in Dashboard module | E8: Web UI - Dashboard - Verify navigation drawer opening and item selection (#7) | F8: Ensure Dashboard web UI component operates seamlessly under Chrome/Firefox/Edge Selenium driver. | G8: Browser session active, navigated to NutriFit Web app Dashboard route. | H8: 1. Open NutriFit Web app on Chrome/Edge. 2. Navigate to Dashboard screen. 3. Click hamburger menu icon, select target sidebar menu item. 4. Capture DOM state and screenshot. | I8: Module: Dashboard, Viewport: 1920x1080, Data: Sidebar nav items | J8: Drawer slides out smoothly and routes user to target page. on Dashboard module. | K8: Pending Execution | L8: Medium | M8: Critical | N8: Not Executed | O8: evidence/sel-web-007_screenshot.png | P8: Automated baseline generation
A9: SEL-WEB-008 | B9: Selenium Web UI Testing | C9: Profile | D9: Verify image lazy loading and fallback rendering in Profile module | E9: Web UI - Profile - Verify image lazy loading and fallback rendering (#8) | F9: Ensure Profile web UI component operates seamlessly under Chrome/Firefox/Edge Selenium driver. | G9: Browser session active, navigated to NutriFit Web app Profile route. | H9: 1. Open NutriFit Web app on Chrome/Edge. 2. Navigate to Profile screen. 3. Scroll down page rapidly to trigger image viewports. 4. Capture DOM state and screenshot. | I9: Module: Profile, Viewport: 1920x1080, Data: High-res recipe / product images | J9: Images display lazy loading placeholders before rendering final image asset cleanly. on Profile module. | K9: Pending Execution | L9: Medium | M9: Major | N9: Not Executed | O9: evidence/sel-web-008_screenshot.png | P9: Automated baseline generation
A10: SEL-WEB-009 | B10: Selenium Web UI Testing | C10: Language Settings | D10: Verify browser back and forward navigation history in Language Settings module | E10: Web UI - Language Settings - Verify browser back and forward navigation history (#9) | F10: Ensure Language Settings web UI component operates seamlessly under Chrome/Firefox/Edge Selenium driver. | G10: Browser session active, navigated to NutriFit Web app Language Settings route. | H10: 1. Open NutriFit Web app on Chrome/Edge. 2. Navigate to Language Settings screen. 3. Navigate from Dashboard -> Shop -> Product Details, click browser Back, then Forward. 4. Capture DOM state and screenshot. | I10: Module: Language Settings, Viewport: 1920x1080, Data: Browser history stack | J10: URL state and page DOM sync perfectly with browser history state. on Language Settings module. | K10: Pending Execution | L10: High | M10: Moderate | N10: Not Executed | O10: evidence/sel-web-009_screenshot.png | P10: Automated baseline generation
A11: SEL-WEB-010 | B11: Selenium Web UI Testing | C11: AI Trainer | D11: Verify accessibility aria-labels and keyboard tab traversal in AI Trainer module | E11: Web UI - AI Trainer - Verify accessibility aria-labels and keyboard tab traversal (#10) | F11: Ensure AI Trainer web UI component operates seamlessly under Chrome/Firefox/Edge Selenium driver. | G11: Browser session active, navigated to NutriFit Web app AI Trainer route. | H11: 1. Open NutriFit Web app on Chrome/Edge. 2. Navigate to AI Trainer screen. 3. Press TAB key repeatedly from top of web page to traverse focusable elements. 4. Capture DOM state and screenshot. | I11: Module: AI Trainer, Viewport: 1920x1080, Data: Keyboard navigation | J11: Focus outline highlights each interactive element in logical DOM sequence. on AI Trainer module. | K11: Pending Execution | L11: Low | M11: Major | N11: Not Executed | O11: evidence/sel-web-010_screenshot.png | P11: Automated baseline generation
A12: SEL-WEB-011 | B12: Selenium Web UI Testing | C12: Workout Plan | D12: Verify page load responsiveness across desktop break points in Workout Plan module | E12: Web UI - Workout Plan - Verify page load responsiveness across desktop break points (#11) | F12: Ensure Workout Plan web UI component operates seamlessly under Chrome/Firefox/Edge Selenium driver. | G12: Browser session active, navigated to NutriFit Web app Workout Plan route. | H12: 1. Open NutriFit Web app on Chrome/Edge. 2. Navigate to Workout Plan screen. 3. Launch web browser at 1920x1080 resolution, navigate to portal, verify layout grid and header alignment. 4. Capture DOM state and screenshot. | I12: Module: Workout Plan, Viewport: 1920x1080, Data: Standard viewport 1920x1080 | J12: Layout scales seamlessly without horizontal overflow or overlapping text elements. on Workout Plan module. | K12: Pending Execution | L12: Medium | M12: Moderate | N12: Not Executed | O12: evidence/sel-web-011_screenshot.png | P12: Automated baseline generation
... A101: SEL-WEB-100 | B101: Selenium Web UI Testing | C101: Checkout | D101: Verify accessibility aria-labels and keyboard tab traversal in Checkout module | E101: Web UI - Checkout - Verify accessibility aria-labels and keyboard tab traversal (#100) | F101: Ensure Checkout web UI component operates seamlessly under Chrome/Firefox/Edge Selenium driver. | G101: Browser session active, navigated to NutriFit Web app Checkout route. | H101: 1. Open NutriFit Web app on Chrome/Edge. 2. Navigate to Checkout screen. 3. Press TAB key repeatedly from top of web page to traverse focusable elements. 4. Capture DOM state and screenshot. | I101: Module: Checkout, Viewport: 1920x1080, Data: Keyboard navigation | J101: Focus outline highlights each interactive element in logical DOM sequence. on Checkout module. | K101: Pending Execution | L101: Low | M101: Major | N101: Not Executed | O101: evidence/sel-web-100_screenshot.png | P101: Automated baseline generation

Sheet Appium E2E Tests
A1: Test Case ID | B1: Testing Type | C1: Module | D1: Test Scenario | E1: Test Case Title | F1: Objective | G1: Preconditions | H1: Test Steps | I1: Test Data | J1: Expected Result | K1: Actual Result | L1: Priority | M1: Severity | N1: Status | O1: Evidence Path | P1: Remarks
A2: APP-AND-001 | B2: Appium Android E2E Testing | C2: Splash | D2: Verify native touch swipe and scroll gestures for Android Splash | E2: Android E2E - Splash - Verify native touch swipe and scroll gestures (#1) | F2: Verify native Android application behavior for Splash using Appium automation. | G2: NutriFit APK installed on Android Emulator/Device (API level 33+), Appium session running. | H2: 1. Launch Appium driver session. 2. Open Splash view via native element selector. 3. Perform vertical swipe gesture on scrollable listview container. 4. Verify UI state. | I2: Device: Pixel 7 Pro (API 34), Package: com.nutrifit.app, Module: Splash | J2: Container scrolls smoothly without frame drops or touch drag locking. for Splash screen on Android. | K2: Pending Execution | L2: Medium | M2: Moderate | N2: Not Executed | O2: evidence/app-and-001_screenshot.png | P2: Automated baseline generation
A3: APP-AND-002 | B3: Appium Android E2E Testing | C3: Login | D3: Verify hardware back button behavior for Android Login | E3: Android E2E - Login - Verify hardware back button behavior (#2) | F3: Verify native Android application behavior for Login using Appium automation. | G3: NutriFit APK installed on Android Emulator/Device (API level 33+), Appium session running. | H3: 1. Launch Appium driver session. 2. Open Login view via native element selector. 3. Navigate deep into feature stack, press hardware back button. 4. Verify UI state. | I3: Device: Pixel 7 Pro (API 34), Package: com.nutrifit.app, Module: Login | J3: App returns to previous screen cleanly without exiting app unexpectedly. for Login screen on Android. | K3: Pending Execution | L3: High | M3: Moderate | N3: Not Executed | O3: evidence/app-and-002_screenshot.png | P3: Automated baseline generation
A4: APP-AND-003 | B4: Appium Android E2E Testing | C4: Signup | D4: Verify device orientation toggle (Portrait to Landscape) for Android Signup | E4: Android E2E - Signup - Verify device orientation toggle (Portrait to Landscape) (#3) | F4: Verify native Android application behavior for Signup using Appium automation. | G4: NutriFit APK installed on Android Emulator/Device (API level 33+), Appium session running. | H4: 1. Launch Appium driver session. 2. Open Signup view via native element selector. 3. Trigger device rotation to landscape, verify view adaptation. 4. Verify UI state. | I4: Device: Pixel 7 Pro (API 34), Package: com.nutrifit.app, Module: Signup | J4: UI resizes responsively in landscape without clipping key buttons. for Signup screen on Android. | K4: Pending Execution | L4: Medium | M4: Major | N4: Not Executed | O4: evidence/app-and-003_screenshot.png | P4: Automated baseline generation
A5: APP-AND-004 | B5: Appium Android E2E Testing | C5: Forgot Password | D5: Verify system notification banner pop-up and tap action for Android Forgot Password | E5: Android E2E - Forgot Password - Verify system notification banner pop-up and tap action (#4) | F5: Verify native Android application behavior for Forgot Password using Appium automation. | G5: NutriFit APK installed on Android Emulator/Device (API level 33+), Appium session running. | H5: 1. Launch Appium driver session. 2. Open Forgot Password view via native element selector. 3. Trigger local push alert, pull down Android notification shade, tap notification. 4. Verify UI state. | I5: Device: Pixel 7 Pro (API 34), Package: com.nutrifit.app, Module: Forgot Password | J5: App opens target screen specified in notification payload. for Forgot Password screen on Android. | K5: Pending Execution | L5: High | M5: Moderate | N5: Not Executed | O5: evidence/app-and-004_screenshot.png | P5: Automated baseline generation
A6: APP-AND-005 | B6: Appium Android E2E Testing | C6: Email Verification | D6: Verify biometric authentication prompt (Fingerprint/Face) for Android Email Verification | E6: Android E2E - Email Verification - Verify biometric authentication prompt (Fingerprint/Face) (#5) | F6: Verify native Android application behavior for Email Verification using Appium automation. | G6: NutriFit APK installed on Android Emulator/Device (API level 33+), Appium session running. | H6: 1. Launch Appium driver session. 2. Open Email Verification view via native element selector. 3. Trigger sensitive action requiring biometric authentication. 4. Verify UI state. | I6: Device: Pixel 7 Pro (API 34), Package: com.nutrifit.app, Module: Email Verification | J6: Native Android BiometricPrompt appears; success unlocks target view. for Email Verification screen on Android. | K6: Pending Execution | L6: Medium | M6: Moderate | N6: Not Executed | O6: evidence/app-and-005_screenshot.png | P6: Automated baseline generation
A7: APP-AND-006 | B7: Appium Android E2E Testing | C7: Onboarding | D7: Verify camera permission request dialog and image capture for Android Onboarding | E7: Android E2E - Onboarding - Verify camera permission request dialog and image capture (#6) | F7: Verify native Android application behavior for Onboarding using Appium automation. | G7: NutriFit APK installed on Android Emulator/Device (API level 33+), Appium session running. | H7: 1. Launch Appium driver session. 2. Open Onboarding view via native element selector. 3. Tap photo upload button, handle system permission dialog, capture photo. 4. Verify UI state. | I7: Device: Pixel 7 Pro (API 34), Package: com.nutrifit.app, Module: Onboarding | J7: Permission granted dialog works; captured image sets profile/meal avatar. for Onboarding screen on Android. | K7: Pending Execution | L7: High | M7: Major | N7: Not Executed | O7: evidence/app-and-006_screenshot.png | P7: Automated baseline generation
A8: APP-AND-007 | B8: Appium Android E2E Testing | C8: Dashboard | D8: Verify deep link url execution on Android device for Android Dashboard | E8: Android E2E - Dashboard - Verify deep link url execution on Android device (#7) | F8: Verify native Android application behavior for Dashboard using Appium automation. | G8: NutriFit APK installed on Android Emulator/Device (API level 33+), Appium session running. | H8: 1. Launch Appium driver session. 2. Open Dashboard view via native element selector. 3. Execute adb command to launch deep link URI target into app. 4. Verify UI state. | I8: Device: Pixel 7 Pro (API 34), Package: com.nutrifit.app, Module: Dashboard | J8: App launches directly into target product details view. for Dashboard screen on Android. | K8: Pending Execution | L8: Medium | M8: Moderate | N8: Not Executed | O8: evidence/app-and-007_screenshot.png | P8: Automated baseline generation
A9: APP-AND-008 | B9: Appium Android E2E Testing | C9: Profile | D9: Verify app backgrounding and resume lifecycle state for Android Profile | E9: Android E2E - Profile - Verify app backgrounding and resume lifecycle state (#8) | F9: Verify native Android application behavior for Profile using Appium automation. | G9: NutriFit APK installed on Android Emulator/Device (API level 33+), Appium session running. | H9: 1. Launch Appium driver session. 2. Open Profile view via native element selector. 3. Press Home button to send app to background for 30s, then re-open app. 4. Verify UI state. | I9: Device: Pixel 7 Pro (API 34), Package: com.nutrifit.app, Module: Profile | J9: App resumes state intact without memory leak or session logout. for Profile screen on Android. | K9: Pending Execution | L9: High | M9: Moderate | N9: Not Executed | O9: evidence/app-and-008_screenshot.png | P9: Automated baseline generation
A10: APP-AND-009 | B10: Appium Android E2E Testing | C10: Language Settings | D10: Verify dark theme integration with Android system settings for Android Language Settings | E10: Android E2E - Language Settings - Verify dark theme integration with Android system settings (#9) | F10: Verify native Android application behavior for Language Settings using Appium automation. | G10: NutriFit APK installed on Android Emulator/Device (API level 33+), Appium session running. | H10: 1. Launch Appium driver session. 2. Open Language Settings view via native element selector. 3. Toggle system-wide Android Dark Theme switch from quick settings. 4. Verify UI state. | I10: Device: Pixel 7 Pro (API 34), Package: com.nutrifit.app, Module: Language Settings | J10: NutriFit automatically adapts to OS dark theme preference. for Language Settings screen on Android. | K10: Pending Execution | L10: Medium | M10: Major | N10: Not Executed | O10: evidence/app-and-009_screenshot.png | P10: Automated baseline generation
A11: APP-AND-010 | B11: Appium Android E2E Testing | C11: AI Trainer | D11: Verify offline cached state when switching Airplane mode for Android AI Trainer | E11: Android E2E - AI Trainer - Verify offline cached state when switching Airplane mode (#10) | F11: Verify native Android application behavior for AI Trainer using Appium automation. | G11: NutriFit APK installed on Android Emulator/Device (API level 33+), Appium session running. | H11: 1. Launch Appium driver session. 2. Open AI Trainer view via native element selector. 3. Turn on Airplane Mode on device, navigate app screens. 4. Verify UI state. | I11: Device: Pixel 7 Pro (API 34), Package: com.nutrifit.app, Module: AI Trainer | J11: App displays offline warning banner while serving cached data gracefully. for AI Trainer screen on Android. | K11: Pending Execution | L11: High | M11: Moderate | N11: Not Executed | O11: evidence/app-and-010_screenshot.png | P11: Automated baseline generation
A12: APP-AND-011 | B12: Appium Android E2E Testing | C12: Workout Plan | D12: Verify native touch swipe and scroll gestures for Android Workout Plan | E12: Android E2E - Workout Plan - Verify native touch swipe and scroll gestures (#11) | F12: Verify native Android application behavior for Workout Plan using Appium automation. | G12: NutriFit APK installed on Android Emulator/Device (API level 33+), Appium session running. | H12: 1. Launch Appium driver session. 2. Open Workout Plan view via native element selector. 3. Perform vertical swipe gesture on scrollable listview container. 4. Verify UI state. | I12: Device: Pixel 7 Pro (API 34), Package: com.nutrifit.app, Module: Workout Plan | J12: Container scrolls smoothly without frame drops or touch drag locking. for Workout Plan screen on Android. | K12: Pending Execution | L12: Medium | M12: Moderate | N12: Not Executed | O12: evidence/app-and-011_screenshot.png | P12: Automated baseline generation
... A91: APP-AND-090 | B91: Appium Android E2E Testing | C91: Sleep Tracker | D91: Verify offline cached state when switching Airplane mode for Android Sleep Tracker | E91: Android E2E - Sleep Tracker - Verify offline cached state when switching Airplane mode (#90) | F91: Verify native Android application behavior for Sleep Tracker using Appium automation. | G91: NutriFit APK installed on Android Emulator/Device (API level 33+), Appium session running. | H91: 1. Launch Appium driver session. 2. Open Sleep Tracker view via native element selector. 3. Turn on Airplane Mode on device, navigate app screens. 4. Verify UI state. | I91: Device: Pixel 7 Pro (API 34), Package: com.nutrifit.app, Module: Sleep Tracker | J91: App displays offline warning banner while serving cached data gracefully. for Sleep Tracker screen on Android. | K91: Pending Execution | L91: High | M91: Major | N91: Not Executed | O91: evidence/app-and-090_screenshot.png | P91: Automated baseline generation

Sheet Flutter Tests
